 <model name='racecar' canonical_link='chassis'>

        <pose relative_to='world'>0 0 0 0 0 0</pose>

        <frame name="lidar_frame" attached_to='chassis'>
            <pose>0.8 0 0.5 0 0 0</pose>
        </frame>

        <plugin
            filename="libignition-gazebo-diff-drive-system.so"
            name="ignition::gazebo::systems::DiffDrive">
            <left_joint>front_left_wheel_joint</left_joint>
            <right_joint>front_right_wheel_joint</right_joint>
            <wheel_separation>1.2</wheel_separation>
            <wheel_radius>0.3</wheel_radius>
            <odom_publish_frequency>1</odom_publish_frequency>
            <topic>cmd_vel</topic>
        </plugin>

        <link name='chassis'>
            <pose relative_to='__model__'>0.3302 0 0.0708 0 0 0</pose>

        <inertial> <!--inertial properties of the link mass, inertia matix-->
            <mass>1.14395</mass>
            <inertia>
                <ixx>0.00757</ixx>
                <ixy>0</ixy>
                <ixz>0</ixz>
                <iyy>0.019989</iyy>
                <iyz>0</iyz>
                <izz>0.027559</izz>
            </inertia>
        </inertial>    

        <visual name='visual'>
            <geometry>
                <box>
                    <size>0.3302 0.2032 0.1</size>
                </box>
            </geometry>
            <!--let's add color to our link-->
            <material>
                <ambient>0.0 0.0 1.0 1</ambient>
                <diffuse>0.0 0.0 1.0 1</diffuse>
                <specular>0.0 0.0 1.0 1</specular>
            </material>
        </visual>

            <collision name='collision'>
                <geometry>
                    <box>
                        <size>0.3302 0.2032 0.1</size>
                    </box>
                </geometry>
            </collision>

            <sensor name="imu_sensor" type="imu">
                <always_on>1</always_on>
                <update_rate>1</update_rate>
                <visualize>true</visualize>
                <topic>imu</topic>
            </sensor>

            <sensor name='gpu_lidar' type='gpu_lidar'>"
                <pose relative_to='lidar_frame'>0 0 0 0 0 0</pose>
                <topic>lidar</topic>
                <update_rate>10</update_rate>
                <ray>
                    <scan>
                        <horizontal>
                            <samples>640</samples>
                            <resolution>1</resolution>
                            <min_angle>-1.396263</min_angle>
                            <max_angle>1.396263</max_angle>
                        </horizontal>
                        <vertical>
                            <samples>1</samples>
                            <resolution>0.01</resolution>
                            <min_angle>0</min_angle>
                            <max_angle>0</max_angle>
                        </vertical>
                    </scan>
                    <range>
                        <min>0.08</min>
                        <max>10.0</max>
                        <resolution>0.01</resolution>
                    </range>
                </ray>
                <always_on>1</always_on>
                <visualize>true</visualize>
            </sensor>
        </link>
        
        <link name='left_wheel'>
            <pose relative_to="chassis">0.165 0.13 -0.020 -1.5707 0 0</pose>
                <inertial>
                    <mass>0.22</mass>
                    <inertia>
                        <ixx>0.000169</ixx>
                        <ixy>0</ixy>
                        <ixz>0</ixz>
                        <iyy>0.000169</iyy>
                        <iyz>0</iyz>
                        <izz>0.000284</izz>
                    </inertia>
                </inertial>

            <visual name='visual'>
            <geometry>
                <cylinder>
                    <radius>0.0508</radius>
                    <length>0.0381</length>
                </cylinder>
            </geometry>
            <material>
                <ambient>1.0 0.0 0.0 1</ambient>
                <diffuse>1.0 0.0 0.0 1</diffuse>
                <specular>1.0 0.0 0.0 1</specular>
            </material>
            </visual>
            <collision name='collision'>
                <geometry>
                    <cylinder>
                        <radius>0.0508</radius>
                        <length>0.0381</length>
                    </cylinder>
                </geometry>
            </collision>
        </link>

        <link name='right_wheel'>
            <pose relative_to="chassis">0.165 -0.13 -0.020 -1.5707 0 0</pose>
                <inertial>
                    <mass>0.22</mass>
                    <inertia>
                        <ixx>0.000169</ixx>
                        <ixy>0</ixy>
                        <ixz>0</ixz>
                        <iyy>0.000169</iyy>
                        <iyz>0</iyz>
                        <izz>0.000284</izz>
                    </inertia>
                </inertial>

            <visual name='visual'>
            <geometry>
                <cylinder>
                    <radius>0.0508</radius>
                    <length>0.0381</length>
                </cylinder>
            </geometry>
            <material>
                <ambient>1.0 0.0 0.0 1</ambient>
                <diffuse>1.0 0.0 0.0 1</diffuse>
                <specular>1.0 0.0 0.0 1</specular>
            </material>
            </visual>
            <collision name='collision'>
                <geometry>
                    <cylinder>
                        <radius>0.0508</radius>
                        <length>0.0381</length>
                    </cylinder>
                </geometry>
            </collision>
        </link>

        <!--The same as left wheel but with different position-->
        <link name='right_rear_wheel'>
            <pose relative_to="chassis">-0.165 -0.13 -0.020 -1.5707 0 0</pose> <!--angles are in radian-->
            <inertial>
                <mass>0.22</mass>
                <inertia>
                    <ixx>0.000169</ixx>
                    <ixy>0</ixy>
                    <ixz>0</ixz>
                    <iyy>0.000169</iyy>
                    <iyz>0</iyz>
                    <izz>0.000284</izz>
                </inertia>
            </inertial>
            <visual name='visual'>
                <geometry>
                    <cylinder>
                        <radius>0.0508</radius>
                        <length>0.0381</length>
                    </cylinder>
                </geometry>
                <material>
                    <ambient>1.0 0.0 0.0 1</ambient>
                    <diffuse>1.0 0.0 0.0 1</diffuse>
                    <specular>1.0 0.0 0.0 1</specular>
                </material>
            </visual>
            <collision name='collision'>
                <geometry>
                    <cylinder>
                        <radius>0.0508</radius>
                        <length>0.0381</length>
                    </cylinder>
                </geometry>
            </collision>
        </link>

        <link name='left_rear_wheel'>
            <pose relative_to="chassis">-0.165 0.13 -0.020 -1.5707 0 0</pose> <!--angles are in radian-->
            <inertial>
                <mass>0.22</mass>
                <inertia>
                    <ixx>0.000169</ixx>
                    <ixy>0</ixy>
                    <ixz>0</ixz>
                    <iyy>0.000169</iyy>
                    <iyz>0</iyz>
                    <izz>0.000284</izz>
                </inertia>
            </inertial>
            <visual name='visual'>
                <geometry>
                    <cylinder>
                        <radius>0.0508</radius>
                        <length>0.0381</length>
                    </cylinder>
                </geometry>
                <material>
                    <ambient>1.0 0.0 0.0 1</ambient>
                    <diffuse>1.0 0.0 0.0 1</diffuse>
                    <specular>1.0 0.0 0.0 1</specular>
                </material>
            </visual>
            <collision name='collision'>
                <geometry>
                    <cylinder>
                        <radius>0.0508</radius>
                        <length>0.0381</length>
                    </cylinder>
                </geometry>
            </collision>
        </link>

        <link name='lidar'>
            <pose relative_to="chassis">0.10 0.0 0.06905 0 0 0</pose> <!--angles are in radian-->
            <inertial>
                <mass>0.05</mass>
                <inertia>
                    <ixx>0.000406</ixx>
                    <ixy>0</ixy>
                    <ixz>0</ixz>
                    <iyy>0.000406</iyy>
                    <iyz>0</iyz>
                    <izz>0.00001</izz>
                </inertia>
            </inertial>
            <visual name='visual'>
                <geometry>
                    <cylinder>
                        <radius>0.0508</radius>
                        <length>0.0381</length>
                    </cylinder>
                </geometry>
                <material>
                    <ambient>1.0 0.0 0.0 1</ambient>
                    <diffuse>1.0 0.0 0.0 1</diffuse>
                    <specular>1.0 0.0 0.0 1</specular>
                </material>
            </visual>
            <collision name='collision'>
                <geometry>
                    <cylinder>
                        <radius>0.0508</radius>
                        <length>0.0381</length>
                    </cylinder>
                </geometry>
            </collision>
        </link>

        <link name="front_left_wheel_steering_link">
            <pose relative_to="chassis">0.165 0.10 -0.020 0 0 0</pose>
            <inertial>
            <mass>0.1</mass>
            <inertia>
                <ixx>8e-6</ixx>
                <iyy>8e-6</iyy>
                <izz>1e-6</izz>
            </inertia>
            </inertial>
            <visual name="steering_link_visual">
            <pose>0 0 0 0 0 0</pose>
            <geometry>
                <cylinder>
                <length>0.03</length>
                <radius>0.005</radius>
                </cylinder>
            </geometry>
            <material>
                <ambient>1 1 1</ambient>
                <diffuse>1 1 1</diffuse>
            </material>
            </visual>
        </link>

        <link name="front_right_wheel_steering_link">
            <pose relative_to="chassis">0.165 -0.10 -0.020 0 0 0</pose>
            <inertial>
            <mass>0.1</mass>
            <inertia>
                <ixx>8e-6</ixx>
                <iyy>8e-6</iyy>
                <izz>1e-6</izz>
            </inertia>
            </inertial>
            <visual name="steering_link_visual">
            <pose>0 0 0 0 0 0</pose>
            <geometry>
                <cylinder>
                <length>0.03</length>
                <radius>0.005</radius>
                </cylinder>
            </geometry>
            <material>
                <ambient>1 1 1</ambient>
                <diffuse>1 1 1</diffuse>
            </material>
            </visual>
        </link>

        <joint name='front_left_wheel_joint' type='revolute'>
            <pose relative_to='left_wheel'/>
            <parent>chassis</parent>
            <child>left_wheel</child>
            <axis>
                <xyz expressed_in='__model__'>0 1 0</xyz> <!--can be defined as any frame or even arbitrary frames-->
                <limit>
                    <lower>-1.79769e+308</lower>    <!--negative infinity-->
                    <upper>1.79769e+308</upper>     <!--positive infinity-->
                </limit>
            </axis>
        </joint>

        <joint name='front_right_wheel_joint' type='revolute'>
            <pose relative_to='right_wheel'/>
            <parent>chassis</parent>
            <child>right_wheel</child>
            <axis>
                <xyz expressed_in='__model__'>0 1 0</xyz>
                <limit>
                    <lower>-1.79769e+308</lower>    <!--negative infinity-->
                    <upper>1.79769e+308</upper>     <!--positive infinity-->
                </limit>
            </axis>
        </joint>

        <joint name='rear_right_wheel_joint' type='revolute'>
            <pose relative_to='right_rear_wheel'/>
            <parent>chassis</parent>
            <child>right_rear_wheel</child>
            <axis>
                <xyz expressed_in='__model__'>0 1 0</xyz>
                <limit>
                    <lower>-1.79769e+308</lower>    <!--negative infinity-->
                    <upper>1.79769e+308</upper>     <!--positive infinity-->
                </limit>
            </axis>
        </joint>

        <joint name='rear_left_wheel_joint' type='revolute'>
            <pose relative_to='left_rear_wheel'/>
            <parent>chassis</parent>
            <child>left_rear_wheel</child>
            <axis>
                <xyz expressed_in='__model__'>0 1 0</xyz>
                <limit>
                    <lower>-1.79769e+308</lower>    <!--negative infinity-->
                    <upper>1.79769e+308</upper>     <!--positive infinity-->
                </limit>
            </axis>
        </joint>

        <joint name='lidar_joint' type='revolute'>
            <pose relative_to='chassis'/>
            <parent>chassis</parent>
            <child>lidar</child>
            <axis>
                <xyz expressed_in='__model__'>0 0 1</xyz>
                <limit>
                    <lower>-1.79769e+308</lower>    <!--negative infinity-->
                    <upper>1.79769e+308</upper>     <!--positive infinity-->
                </limit>
            </axis>
        </joint>

        <joint name="front_left_wheel_steering_joint" type="revolute">
            <parent>chassis</parent>
            <child>front_left_wheel_steering_link</child>
            <axis>
            <xyz>0 0 1</xyz>
            <limit>
                <lower>-0.6</lower>
                <upper>+0.6</upper>
                <velocity>1.0</velocity>
                <effort>25</effort>
            </limit>
            <use_parent_model_frame>1</use_parent_model_frame>
            </axis>
        </joint>

        <joint name="front_right_wheel_steering_joint" type="revolute">
            <parent>chassis</parent>
            <child>front_right_wheel_steering_link</child>
            <axis>
            <xyz>0 0 1</xyz>
            <limit>
                <lower>-0.6</lower>
                <upper>+0.6</upper>
                <velocity>1.0</velocity>
                <effort>25</effort>
            </limit>
            </axis>
        </joint>

        <plugin
            filename="ignition-gazebo-ackermann-steering-system"
            name="ignition::gazebo::systems::AckermannSteering">
            <left_joint>front_left_wheel_joint</left_joint>
            <left_joint>rear_left_wheel_joint</left_joint>
            <right_joint>front_right_wheel_joint</right_joint>
            <right_joint>rear_right_wheel_joint</right_joint>
            <left_steering_joint>front_left_wheel_steering_joint</left_steering_joint>
            <right_steering_joint>front_right_wheel_steering_joint</right_steering_joint>
            <kingpin_width>1.0</kingpin_width>
            <steering_limit>0.5</steering_limit>
            <wheel_base>1.0</wheel_base>
            <wheel_separation>1.25</wheel_separation>
            <wheel_radius>0.3</wheel_radius>
            <min_velocity>-1</min_velocity>
            <max_velocity>1</max_velocity>
            <min_acceleration>-3</min_acceleration>
            <max_acceleration>3</max_acceleration>
        </plugin>

    



    </model>