<model name='racecar' canonical_link='chassis'>
    <pose relative_to='world'>0 0 0 0 0 0</pose>

    <link name='chassis'>
        <pose relative_to='__model__'>0.5 0 0.4 0 0 0</pose>

    <inertial> <!--inertial properties of the link mass, inertia matix-->
        <mass>1.14395</mass>
        <inertia>
            <ixx>0.095329</ixx>
            <ixy>0</ixy>
            <ixz>0</ixz>
            <iyy>0.381317</iyy>
            <iyz>0</iyz>
            <izz>0.476646</izz>
        </inertia>
    </inertial>    

    <visual name='visual'>
        <geometry>
            <box>
                <size>2.0 1.0 0.5</size>
            </box>
        </geometry>
        <!--let's add color to our link-->
        <material>
            <ambient>0.0 0.0 1.0 1</ambient>
            <diffuse>0.0 0.0 1.0 1</diffuse>
            <specular>0.0 0.0 1.0 1</specular>
        </material>
    </visual>

     <collision name='collision'>
            <geometry>
                <box>
                    <size>2.0 1.0 0.5</size>
                </box>
            </geometry>
        </collision>
    </link>
    
    <link name='left_wheel'>
        <pose relative_to="chassis">-0.5 0.6 0 -1.5707 0 0</pose>
            <inertial>
                <mass>1</mass>
                <inertia>
                    <ixx>0.043333</ixx>
                    <ixy>0</ixy>
                    <ixz>0</ixz>
                    <iyy>0.043333</iyy>
                    <iyz>0</iyz>
                    <izz>0.08</izz>
                </inertia>
            </inertial>

        <visual name='visual'>
        <geometry>
            <cylinder>
                <radius>0.4</radius>
                <length>0.2</length>
            </cylinder>
        </geometry>
        <material>
            <ambient>1.0 0.0 0.0 1</ambient>
            <diffuse>1.0 0.0 0.0 1</diffuse>
            <specular>1.0 0.0 0.0 1</specular>
        </material>
        </visual>
        <collision name='collision'>
            <geometry>
                <cylinder>
                    <radius>0.4</radius>
                    <length>0.2</length>
                </cylinder>
            </geometry>
        </collision>
    </link>

    <link name='right_wheel'>
        <pose relative_to="chassis"> 0.5 0.6 0 -1.5707 0 0</pose>
            <inertial>
                <mass>1</mass>
                <inertia>
                    <ixx>0.043333</ixx>
                    <ixy>0</ixy>
                    <ixz>0</ixz>
                    <iyy>0.043333</iyy>
                    <iyz>0</iyz>
                    <izz>0.08</izz>
                </inertia>
            </inertial>

        <visual name='visual'>
        <geometry>
            <cylinder>
                <radius>0.4</radius>
                <length>0.2</length>
            </cylinder>
        </geometry>
        <material>
            <ambient>1.0 0.0 0.0 1</ambient>
            <diffuse>1.0 0.0 0.0 1</diffuse>
            <specular>1.0 0.0 0.0 1</specular>
        </material>
        </visual>
        <collision name='collision'>
            <geometry>
                <cylinder>
                    <radius>0.4</radius>
                    <length>0.2</length>
                </cylinder>
            </geometry>
        </collision>
    </link>

    <!--The same as left wheel but with different position-->
    <link name='right_back_wheel'>
        <pose relative_to="chassis">-0.5 -0.6 0 -1.5707 0 0</pose> <!--angles are in radian-->
        <inertial>
            <mass>1</mass>
            <inertia>
                <ixx>0.043333</ixx>
                <ixy>0</ixy>
                <ixz>0</ixz>
                <iyy>0.043333</iyy>
                <iyz>0</iyz>
                <izz>0.08</izz>
            </inertia>
        </inertial>
        <visual name='visual'>
            <geometry>
                <cylinder>
                    <radius>0.4</radius>
                    <length>0.2</length>
                </cylinder>
            </geometry>
            <material>
                <ambient>1.0 0.0 0.0 1</ambient>
                <diffuse>1.0 0.0 0.0 1</diffuse>
                <specular>1.0 0.0 0.0 1</specular>
            </material>
        </visual>
        <collision name='collision'>
            <geometry>
                <cylinder>
                    <radius>0.4</radius>
                    <length>0.2</length>
                </cylinder>
            </geometry>
        </collision>
    </link>

    <link name='left_back_wheel'>
        <pose relative_to="chassis">-0.5 0.6 0 -1.5707 0 0</pose> <!--angles are in radian-->
        <inertial>
            <mass>1</mass>
            <inertia>
                <ixx>0.043333</ixx>
                <ixy>0</ixy>
                <ixz>0</ixz>
                <iyy>0.043333</iyy>
                <iyz>0</iyz>
                <izz>0.08</izz>
            </inertia>
        </inertial>
        <visual name='visual'>
            <geometry>
                <cylinder>
                    <radius>0.4</radius>
                    <length>0.2</length>
                </cylinder>
            </geometry>
            <material>
                <ambient>1.0 0.0 0.0 1</ambient>
                <diffuse>1.0 0.0 0.0 1</diffuse>
                <specular>1.0 0.0 0.0 1</specular>
            </material>
        </visual>
        <collision name='collision'>
            <geometry>
                <cylinder>
                    <radius>0.4</radius>
                    <length>0.2</length>
                </cylinder>
            </geometry>
        </collision>
    </link>

    <joint name='left_wheel_joint' type='revolute'>
        <pose relative_to='left_wheel'/>
        <parent>chassis</parent>
        <child>left_wheel</child>
        <axis>
            <xyz expressed_in='__model__'>0 1 0</xyz> <!--can be defined as any frame or even arbitrary frames-->
            <limit>
                <lower>-1.79769e+308</lower>    <!--negative infinity-->
                <upper>1.79769e+308</upper>     <!--positive infinity-->
            </limit>
        </axis>
    </joint>

    <joint name='right_wheel_joint' type='revolute'>
        <pose relative_to='right_wheel'/>
        <parent>chassis</parent>
        <child>right_wheel</child>
        <axis>
            <xyz expressed_in='__model__'>0 1 0</xyz>
            <limit>
                <lower>-1.79769e+308</lower>    <!--negative infinity-->
                <upper>1.79769e+308</upper>     <!--positive infinity-->
            </limit>
        </axis>
    </joint>

    <joint name='right_back_wheel_joint' type='revolute'>
        <pose relative_to='right_back_wheel'/>
        <parent>chassis</parent>
        <child>right_back_wheel</child>
        <axis>
            <xyz expressed_in='__model__'>0 1 0</xyz>
            <limit>
                <lower>-1.79769e+308</lower>    <!--negative infinity-->
                <upper>1.79769e+308</upper>     <!--positive infinity-->
            </limit>
        </axis>
    </joint>

    <joint name='left_back_wheel_joint' type='revolute'>
        <pose relative_to='left_back_wheel'/>
        <parent>chassis</parent>
        <child>left_back_wheel</child>
        <axis>
            <xyz expressed_in='__model__'>0 1 0</xyz>
            <limit>
                <lower>-1.79769e+308</lower>    <!--negative infinity-->
                <upper>1.79769e+308</upper>     <!--positive infinity-->
            </limit>
        </axis>
    </joint>














</model>


    

